Workbook

Sheet ActualBiomass
A1: Plot | B1: Quadrat | C1: Spp | D1: Actual dry mass + container w/o bag (g) | E1: Container mass (g) | F1: Actual dry mass w/o bag (g) | G1: Max diameter (cm)
A2: A1 | B2: Q4 | C2: Impatiens capensis | D2: 407.11 | E2: 406.57 | F2: =MAX(D2-E2, 0) -> 0.54
A3: B1 | B3: Q2 | C3: Humulus japonicus | D3: 424.37 | E3: 406.5 | F3: =MAX(D3-E3, 0) -> 17.87
A4: B1 | B4: Q4 | C4: Acer saccharinum | D4: 406.74 | E4: 406.55 | F4: =MAX(D4-E4, 0) -> 0.19
A5: B1 | B5: Q4 | C5: Toxicodendron radicans | D5: 406.88 | E5: 406.8 | F5: =MAX(D5-E5, 0) -> 0.08
A6: B1 | B6: Q4 | C6: Urtica gracilis | D6: 487.07 | E6: 406.99 | F6: =MAX(D6-E6, 0) -> 80.08
A7: B1 | B7: Q5 | C7: Humulus japonicus | D7: 420.26 | E7: 406.8 | F7: =MAX(D7-E7, 0) -> 13.46
A8: B1 | B8: Q5 | C8: Phalaris arundinacea | D8: 410.7 | E8: 406.61 | F8: =MAX(D8-E8, 0) -> 4.09
A9: B1 | B9: Q5 | C9: Urtica gracilis | D9: 408.65 | E9: 407.05 | F9: =MAX(D9-E9, 0) -> 1.6
A10: D1 | B10: Q4 | C10: Persicaria punctata | D10: 412.44 | E10: 407.1 | F10: =MAX(D10-E10, 0) -> 5.34
A11: D2 | B11: Q5 | C11: Ageratina altissima | D11: 412 | E11: 406.51 | F11: =MAX(D11-E11, 0) -> 5.49
A12: E3 | B12: Q3 | C12: Humulus japonicus | D12: 437.59 | E12: 406.48 | F12: =MAX(D12-E12, 0) -> 31.11
A13: B1 | B13: Q1 | C13: Herbaceous litter | D13: 480.63 | E13: 406.77 | F13: =MAX(D13-E13, 0) -> 73.86
... A248: B2 | B248: Q4 | C248: Herbaceous litter | D248: 49.83 | E248: 0 | F248: =MAX(D248-E248, 0) -> 49.83
A249: B2 | B249: Q4 | C249: Fine woody debris | D249: 108.62 | E249: 0 | F249: =MAX(D249-E249, 0) -> 108.62 | G249: 1.8
A250: B2 | B250: Q5 | C250: Herbaceous litter | D250: 36.02 | E250: 0 | F250: =MAX(D250-E250, 0) -> 36.02
A251: B2 | B251: Q5 | C251: Fine woody debris | D251: 13.6 | E251: 0 | F251: =MAX(D251-E251, 0) -> 13.6 | G251: 1.3
A252: C1 | B252: Q3 | C252: Herbaceous litter | D252: 38.96 | E252: 0 | F252: =MAX(D252-E252, 0) -> 38.96
A253: C1 | B253: Q3 | C253: Fine woody debris | D253: 13 | E253: 0 | F253: =MAX(D253-E253, 0) -> 13 | G253: 0.7
A254: C1 | B254: Q4 | C254: Herbaceous litter | D254: 25.22 | E254: 0 | F254: =MAX(D254-E254, 0) -> 25.22
A255: C1 | B255: Q4 | C255: Fine woody debris | D255: 0 | E255: 0 | F255: =MAX(D255-E255, 0) -> 0
A256: C1 | B256: Q5 | C256: Herbaceous litter | D256: 28.99 | E256: 0 | F256: =MAX(D256-E256, 0) -> 28.99
A257: C1 | B257: Q5 | C257: Fine woody debris | D257: 0 | E257: 0 | F257: =MAX(D257-E257, 0) -> 0
A258: C3 | B258: Q5 | C258: Herbaceous litter | D258: 27.57 | E258: 0 | F258: =MAX(D258-E258, 0) -> 27.57 | G258: 2.3
A259: C3 | B259: Q5 | C259: Fine woody debris | D259: 76.9 | E259: 0 | F259: =MAX(D259-E259, 0) -> 76.9
A260: C2 | B260: Q3 | C260: Herbaceous litter | D260: 47.43 | E260: 0 | F260: =MAX(D260-E260, 0) -> 47.43
A261: C2 | B261: Q3 | C261: Fine woody debris | D261: 35.01 | E261: 0 | F261: =MAX(D261-E261, 0) -> 35.01
A262: C2 | B262: Q1 | C262: Herbaceous litter | D262: 31.49 | E262: 0 | F262: =MAX(D262-E262, 0) -> 31.49
A263: C2 | B263: Q1 | C263: Fine woody debris | D263: 52.62 | E263: 0 | F263: =MAX(D263-E263, 0) -> 52.62
A264: C2 | B264: Q2 | C264: Herbaceous litter | D264: 80.7 | E264: 0 | F264: =MAX(D264-E264, 0) -> 80.7
A265: C2 | B265: Q2 | C265: Fine woody debris | D265: 109.14 | E265: 0 | F265: =MAX(D265-E265, 0) -> 109.14
A266: B3 | B266: Q2 | C266: Herbaceous litter | D266: 38.99 | E266: 0 | F266: =MAX(D266-E266, 0) -> 38.99 | G266: 2.1
A267: B3 | B267: Q2 | C267: Fine woody debris | D267: 41.97 | E267: 0 | F267: =MAX(D267-E267, 0) -> 41.97
A268: B3 | B268: Q5 | C268: Herbaceous litter | D268: 28.05 | E268: 0 | F268: =MAX(D268-E268, 0) -> 28.05
A269: B3 | B269: Q5 | C269: Fine woody debris | D269: 0 | E269: 0 | F269: =MAX(D269-E269, 0) -> 0 | G269: 0
A270: D1 | B270: Q1 | C270: Herbaceous litter | D270: 27.6 | E270: 0 | F270: =MAX(D270-E270, 0) -> 27.6
A271: D1 | B271: Q1 | C271: Fine woody debris | D271: 0 | E271: 0 | F271: =MAX(D271-E271, 0) -> 0 | G271: 0
A272: D1 | B272: Q2 | C272: Herbaceous litter | D272: 41.85 | E272: 0 | F272: =MAX(D272-E272, 0) -> 41.85
A273: D1 | B273: Q2 | C273: Fine woody debris | D273: 2 | E273: 0 | F273: =MAX(D273-E273, 0) -> 2 | G273: 1
A274: D1 | B274: Q3 | C274: Herbaceous litter | D274: 23.56 | E274: 0 | F274: =MAX(D274-E274, 0) -> 23.56
...

Sheet ActualBiomass_Sorted
A1: Plot | B1: Quadrat | C1: Spp | D1: Actual dry mass + container w/o bag (g) | E1: Container mass (g) | F1: Actual dry mass w/o bag (g) | G1: Max diameter (cm)
A2: A1 | B2: Q1 | C2: Fine woody debris | D2: 28.32 | E2: 0 | F2: 28.32 | G2: 1.5
A3: A1 | B3: Q1 | C3: Herbaceous litter | D3: 45.34 | E3: 0 | F3: 45.34
A4: A1 | B4: Q1 | C4: Pilea pumila | D4: 2.6 | E4: 0 | F4: 2.6
A5: A1 | B5: Q2 | C5: Elymus virginicus | D5: 0.15 | E5: 0 | F5: 0.15
A6: A1 | B6: Q2 | C6: Fine woody debris | D6: 32.01 | E6: 0 | F6: 32.01 | G6: 1.4
A7: A1 | B7: Q2 | C7: Herbaceous litter | D7: 39.63 | E7: 0 | F7: 39.63
A8: A1 | B8: Q2 | C8: Persicaria punctata | D8: 4.54 | E8: 0 | F8: 4.54
A9: A1 | B9: Q2 | C9: Pilea pumila | D9: 5.45 | E9: 0 | F9: 5.45
A10: A1 | B10: Q3 | C10: Fine woody debris | D10: 0 | E10: 0 | F10: 0
A11: A1 | B11: Q3 | C11: Herbaceous litter | D11: 35.14 | E11: 0 | F11: 35.14
A12: A1 | B12: Q3 | C12: Pilea pumila | D12: 3.83 | E12: 0 | F12: 3.83
A13: A1 | B13: Q4 | C13: Acer saccharinum | D13: 0.67 | E13: 0 | F13: 0.67
A14: A1 | B14: Q4 | C14: Fine woody debris | D14: 62.55 | E14: 0 | F14: 62.55 | G14: 2.5
A15: A1 | B15: Q4 | C15: Herbaceous litter | D15: 57.74 | E15: 0 | F15: 57.74
A16: A1 | B16: Q4 | C16: Impatiens capensis | D16: 407.11 | E16: 406.57 | F16: 0.54
A17: A1 | B17: Q4 | C17: Persicaria punctata | D17: 0.69 | E17: 0 | F17: 0.69
A18: A1 | B18: Q4 | C18: Toxicodendron radicans | D18: 0.84 | E18: 0 | F18: 0.84
A19: A1 | B19: Q4 | C19: Ulmus americana | D19: 408.05 | E19: 406.36 | F19: 1.69
A20: A1 | B20: Q5 | C20: Fine woody debris | D20: 25.53 | E20: 0 | F20: 25.53
A21: A1 | B21: Q5 | C21: Fraxinus pennsylvanica | D21: 0.17 | E21: 0 | F21: 0.17
A22: A1 | B22: Q5 | C22: Galium aparine | D22: 0.07 | E22: 0 | F22: 0.07
A23: A1 | B23: Q5 | C23: Herbaceous litter | D23: 39.48 | E23: 0 | F23: 39.48
A24: A1 | B24: Q5 | C24: Sicyos angulatus | D24: 0.86 | E24: 0 | F24: 0.86
A25: A1 | B25: Q5 | C25: Toxicodendron radicans | D25: 0.11 | E25: 0 | F25: 0.11
A26: A1 | B26: Q5 | C26: Viola sororia | D26: 0.41 | E26: 0 | F26: 0.41
... A60: A3 | B60: Q1 | C60: Toxicodendron radicans | D60: 410.11 | E60: 406.36 | F60: 3.75
A61: A3 | B61: Q2 | C61: Fine woody debris | D61: 22.37 | E61: 0 | F61: 22.37 | G61: 1.6
A62: A3 | B62: Q2 | C62: Herbaceous litter | D62: 51.13 | E62: 0 | F62: 51.13
A63: A3 | B63: Q2 | C63: Morus alba | D63: 408.54 | E63: 406.36 | F63: 2.18
A64: A3 | B64: Q2 | C64: Pilea pumila | D64: 407.21 | E64: 406.36 | F64: 0.85
A65: A3 | B65: Q2 | C65: Sicyos angulatus | D65: 410.58 | E65: 406.36 | F65: 4.22
A66: A3 | B66: Q3 | C66: Fine woody debris | D66: 7.68 | E66: 0 | F66: 7.68
A67: A3 | B67: Q3 | C67: Galium aparine | D67: 0.08 | E67: 406.36 | F67: 0
A68: A3 | B68: Q3 | C68: Herbaceous litter | D68: 82.88 | E68: 0 | F68: 82.88
A69: A3 | B69: Q3 | C69: Symphyotrichum ontarionisis | D69: 406.99 | E69: 406.36 | F69: 0.63
A70: A3 | B70: Q4 | C70: Fine woody debris | D70: 2.06 | E70: 0 | F70: 2.06 | G70: 1.2
A71: A3 | B71: Q4 | C71: Galium aparine | D71: 0.02 | E71: 0 | F71: 0.02
A72: A3 | B72: Q4 | C72: Herbaceous litter | D72: 27.09 | E72: 0 | F72: 27.09
A73: A3 | B73: Q4 | C73: Symphyotrichum ontarionisis | D73: 407.34 | E73: 406.36 | F73: 0.98
...

Sheet MassWBag
A1: Prelimary biomass data
A3: Batch | B3: 1 | C3: Plot | D3: Quadrat | E3: Species/type | F3: Bag size | G3: Mass with bag (g)
A4: Start time | B4: 44812.917 | C4: A1 | D4: Q4 | E4: Impatiens capensis | F4: S | G4: 7.07
A5: End time | B5: 44814.5 | C5: B1 | D5: Q1 | E5: Humulus japonicus | F5: M | G5: 98.7
C6: B1 | D6: Q1 | E6: Litter | F6: M | G6: 354.05
C7: B1 | D7: Q2 | E7: Humulus japonicus | F7: M | G7: 44.29
C8: B1 | D8: Q2 | E8: Litter | F8: M | G8: 147.76
C9: B1 | D9: Q3 | E9: Litter | F9: M | G9: 212.45
C10: B1 | D10: Q4 | E10: Acer saccharinum | F10: S | G10: 6.54
C11: B1 | D11: Q4 | E11: Urtica gracilis | F11: M | G11: 191.32
C12: B1 | D12: Q4 | E12: Toxicodendron radicans | F12: S | G12: 6.68
C13: B1 | D13: Q4 | E13: Litter | F13: M | G13: 171.54
C14: B1 | D14: Q5 | E14: Phalaris arundinacea | F14: S | G14: 10.55
C15: B1 | D15: Q5 | E15: Humulus japonicus | F15: M | G15: 42.47
C16: B1 | D16: Q5 | E16: Urtica gracilis | F16: S | G16: 8.21
C17: B1 | D17: Q5 | E17: Litter | F17: M | G17: 200.11
A18: Batch | B18: 2 | C18: A1 | D18: Q1 | E18: Pilea pumila | F18: S | G18: 9.01
A19: Start time | B19: 44814.505 | C19: A1 | D19: Q1 | E19: Litter | F19: S | G19: 76.67
A20: End time | B20: 44816.517 | C20: A1 | D20: Q2 | E20: Litter | F20: S | G20: 77.65
C21: A1 | D21: Q2 | E21: Persicaria punctata | F21: S | G21: 11.02
C22: A1 | D22: Q2 | E22: Elymus virginicus | F22: S | G22: 6.55
C23: A1 | D23: Q2 | E23: Pilea pumila | F23: S | G23: 17.39
C24: A1 | D24: Q3 | E24: Pilea pumila | F24: S | G24: 12.53
C25: A1 | D25: Q3 | E25: Litter | F25: S | G25: 40.27
C26: A1 | D26: Q4 | E26: Toxicodendron radicans | F26: S | G26: 7.26
C27: A1 | D27: Q4 | E27: Ulmus americana | F27: S | G27: 8.23
C28: A1 | D28: Q4 | E28: Acer saccharinum | F28: S | G28: 7.06
C29: A1 | D29: Q4 | E29: Persicaria punctata | F29: S | G29: 7.18
C30: A1 | D30: Q4 | E30: Litter | F30: M | G30: 161.83
C31: A1 | D31: Q5 | E31: Sicyos angulatus | F31: S | G31: 7.21
C32: A1 | D32: Q5 | E32: Toxicodendron radicans | F32: S | G32: 6.41
... C58: E1 | D58: Q3 | E58: Phalaris arundinacea | F58: M | G58: 69.03
A59: Batch | B59: 2 | C59: E1 | D59: Q5 | E59: Sicyos angulatus | F59: S | G59: 9.97
A60: Start time | B60: 44814.537 | C60: R3 | D60: Q4 | E60: Acer saccharinum | F60: S | G60: 8.46
A61: End time | B61: 44818.522 | C61: R2 | D61: Q4 | E61: Vitis riparia | F61: S | G61: 7.89
C62: E1 | D62: Q5 | E62: Phalaris arundinacea | F62: M | G62: 71.5
C63: R3 | D63: Q5 | E63: Litter | F63: S | G63: 28.16
C64: R3 | D64: Q4 | E64: Scutellaria lateriflora | F64: S | G64: 9.45
C65: E1 | D65: Q1 | E65: Litter | F65: M | G65: 207.59
C66: R3 | D66: Q1 | E66: Pilea pumila | F66: S | G66: 6.51
...

Sheet PrelimBiomass
A1: Plot | B1: Quadrat | C1: Spp | D1: Bag | E1: Dry mass w/ bag (g) | F1: Estimated dry mass w/o bag (g) | G1: Comment
A2: A1 | B2: Q1 | C2: Litter | D2: S | E2: 76.67 | F2: =MAX(E2-IF(D2="S",BagMasses!$B$12,IF(D2="M",BagMasses!$C$12,IF(D2="L",BagMasses!$D$12,IF(D2="SM",BagMasses!$E$12,IF(D2="E",BagMasses!$F$12))))),0) -> 70.137
A3: A1 | B3: Q1 | C3: Pilea pumila | D3: S | E3: 9.01 | F3: =MAX(E3-IF(D3="S",BagMasses!$B$12,IF(D3="M",BagMasses!$C$12,IF(D3="L",BagMasses!$D$12,IF(D3="SM",BagMasses!$E$12,IF(D3="E",BagMasses!$F$12))))),0) -> 2.477
A4: A1 | B4: Q2 | C4: Elymus virginicus | D4: S | E4: 6.55 | F4: =MAX(E4-IF(D4="S",BagMasses!$B$12,IF(D4="M",BagMasses!$C$12,IF(D4="L",BagMasses!$D$12,IF(D4="SM",BagMasses!$E$12,IF(D4="E",BagMasses!$F$12))))),0) -> 0.017
A5: A1 | B5: Q2 | C5: Litter | D5: S | E5: 77.65 | F5: =MAX(E5-IF(D5="S",BagMasses!$B$12,IF(D5="M",BagMasses!$C$12,IF(D5="L",BagMasses!$D$12,IF(D5="SM",BagMasses!$E$12,IF(D5="E",BagMasses!$F$12))))),0) -> 71.117
A6: A1 | B6: Q2 | C6: Persicaria punctata | D6: S | E6: 11.02 | F6: =MAX(E6-IF(D6="S",BagMasses!$B$12,IF(D6="M",BagMasses!$C$12,IF(D6="L",BagMasses!$D$12,IF(D6="SM",BagMasses!$E$12,IF(D6="E",BagMasses!$F$12))))),0) -> 4.487
A7: A1 | B7: Q2 | C7: Pilea pumila | D7: S | E7: 17.39 | F7: =MAX(E7-IF(D7="S",BagMasses!$B$12,IF(D7="M",BagMasses!$C$12,IF(D7="L",BagMasses!$D$12,IF(D7="SM",BagMasses!$E$12,IF(D7="E",BagMasses!$F$12))))),0) -> 10.857
A8: A1 | B8: Q3 | C8: Litter | D8: S | E8: 40.27 | F8: =MAX(E8-IF(D8="S",BagMasses!$B$12,IF(D8="M",BagMasses!$C$12,IF(D8="L",BagMasses!$D$12,IF(D8="SM",BagMasses!$E$12,IF(D8="E",BagMasses!$F$12))))),0) -> 33.737
A9: A1 | B9: Q3 | C9: Pilea pumila | D9: S | E9: 12.53 | F9: =MAX(E9-IF(D9="S",BagMasses!$B$12,IF(D9="M",BagMasses!$C$12,IF(D9="L",BagMasses!$D$12,IF(D9="SM",BagMasses!$E$12,IF(D9="E",BagMasses!$F$12))))),0) -> 5.997
A10: A1 | B10: Q4 | C10: Acer saccharinum | D10: S | E10: 7.06 | F10: =MAX(E10-IF(D10="S",BagMasses!$B$12,IF(D10="M",BagMasses!$C$12,IF(D10="L",BagMasses!$D$12,IF(D10="SM",BagMasses!$E$12,IF(D10="E",BagMasses!$F$12))))),0) -> 0.527
A11: A1 | B11: Q4 | C11: Impatiens capensis | D11: S | E11: 7.07 | F11: =MAX(E11-IF(D11="S",BagMasses!$B$12,IF(D11="M",BagMasses!$C$12,IF(D11="L",BagMasses!$D$12,IF(D11="SM",BagMasses!$E$12,IF(D11="E",BagMasses!$F$12))))),0) -> 0.537
A12: A1 | B12: Q4 | C12: Litter | D12: M | E12: 161.83 | F12: =MAX(E12-IF(D12="S",BagMasses!$B$12,IF(D12="M",BagMasses!$C$12,IF(D12="L",BagMasses!$D$12,IF(D12="SM",BagMasses!$E$12,IF(D12="E",BagMasses!$F$12))))),0) -> 135.412
A13: A1 | B13: Q4 | C13: Persicaria punctata | D13: S | E13: 7.18 | F13: =MAX(E13-IF(D13="S",BagMasses!$B$12,IF(D13="M",BagMasses!$C$12,IF(D13="L",BagMasses!$D$12,IF(D13="SM",BagMasses!$E$12,IF(D13="E",BagMasses!$F$12))))),0) -> 0.647
... A195: D2 | B195: Q5 | C195: Pilea pumila | D195: S | E195: 19.41 | F195: =MAX(E195-IF(D195="S",BagMasses!$B$12,IF(D195="M",BagMasses!$C$12,IF(D195="L",BagMasses!$D$12,IF(D195="SM",BagMasses!$E$12,IF(D195="E",BagMasses!$F$12))))),0) -> 12.877
A196: D2 | B196: Q5 | C196: Sicyos angulatus | D196: SM | E196: 19.46 | F196: =MAX(E196-IF(D196="S",BagMasses!$B$12,IF(D196="M",BagMasses!$C$12,IF(D196="L",BagMasses!$D$12,IF(D196="SM",BagMasses!$E$12,IF(D196="E",BagMasses!$F$12))))),0) -> 8.1733333 | G196: =F179+F182+F185+F188+F194 -> 410.79667
A197: D3 | B197: Q1 | C197: Litter | D197: L | E197: 204.76 | F197: =MAX(E197-IF(D197="S",BagMasses!$B$12,IF(D197="M",BagMasses!$C$12,IF(D197="L",BagMasses!$D$12,IF(D197="SM",BagMasses!$E$12,IF(D197="E",BagMasses!$F$12))))),0) -> 137.15667
A198: D3 | B198: Q1 | C198: Phalaris arundinacea | D198: SM | E198: 34.01 | F198: =MAX(E198-IF(D198="S",BagMasses!$B$12,IF(D198="M",BagMasses!$C$12,IF(D198="L",BagMasses!$D$12,IF(D198="SM",BagMasses!$E$12,IF(D198="E",BagMasses!$F$12))))),0) -> 22.723333
A199: D3 | B199: Q1 | C199: Sicyos angulatus | D199: E | E199: 3.08 | F199: =MAX(E199-IF(D199="S",BagMasses!$B$12,IF(D199="M",BagMasses!$C$12,IF(D199="L",BagMasses!$D$12,IF(D199="SM",BagMasses!$E$12,IF(D199="E",BagMasses!$F$12))))),0) -> 0.083333333
A200: D3 | B200: Q2 | C200: Litter | D200: SM | E200: 142.14 | F200: =MAX(E200-IF(D200="S",BagMasses!$B$12,IF(D200="M",BagMasses!$C$12,IF(D200="L",BagMasses!$D$12,IF(D200="SM",BagMasses!$E$12,IF(D200="E",BagMasses!$F$12))))),0) -> 130.85333
A201: D3 | B201: Q3 | C201: Litter | D201: SM | E201: 154.09 | F201: =MAX(E201-IF(D201="S",BagMasses!$B$12,IF(D201="M",BagMasses!$C$12,IF(D201="L",BagMasses!$D$12,IF(D201="SM",BagMasses!$E$12,IF(D201="E",BagMasses!$F$12))))),0) -> 142.80333
A202: D3 | B202: Q3 | C202: Sicyos angulatus | D202: E | E202: 3.14 | F202: =MAX(E202-IF(D202="S",BagMasses!$B$12,IF(D202="M",BagMasses!$C$12,IF(D202="L",BagMasses!$D$12,IF(D202="SM",BagMasses!$E$12,IF(D202="E",BagMasses!$F$12))))),0) -> 0.14333333
A203: D3 | B203: Q4 | C203: Litter | D203: SM | E203: 105.34 | F203: =MAX(E203-IF(D203="S",BagMasses!$B$12,IF(D203="M",BagMasses!$C$12,IF(D203="L",BagMasses!$D$12,IF(D203="SM",BagMasses!$E$12,IF(D203="E",BagMasses!$F$12))))),0) -> 94.053333
A204: D3 | B204: Q5 | C204: Litter | D204: SM | E204: 115.94 | F204: =MAX(E204-IF(D204="S",BagMasses!$B$12,IF(D204="M",BagMasses!$C$12,IF(D204="L",BagMasses!$D$12,IF(D204="SM",BagMasses!$E$12,IF(D204="E",BagMasses!$F$12))))),0) -> 104.65333 | G204: =F197+F200+F201+F203+F204 -> 609.52
A205: E1 | B205: Q1 | C205: Humulus japonicus | D205: M | E205: 70.59 | F205: =MAX(E205-IF(D205="S",BagMasses!$B$12,IF(D205="M",BagMasses!$C$12,IF(D205="L",BagMasses!$D$12,IF(D205="SM",BagMasses!$E$12,IF(D205="E",BagMasses!$F$12))))),0) -> 44.172
A206: E1 | B206: Q1 | C206: Litter | D206: M | E206: 207.59 | F206: =MAX(E206-IF(D206="S",BagMasses!$B$12,IF(D206="M",BagMasses!$C$12,IF(D206="L",BagMasses!$D$12,IF(D206="SM",BagMasses!$E$12,IF(D206="E",BagMasses!$F$12))))),0) -> 181.172
A207: E1 | B207: Q2 | C207: Humulus japonicus | D207: M | E207: 127.5 | F207: =MAX(E207-IF(D207="S",BagMasses!$B$12,IF(D207="M",BagMasses!$C$12,IF(D207="L",BagMasses!$D$12,IF(D207="SM",BagMasses!$E$12,IF(D207="E",BagMasses!$F$12))))),0) -> 101.082
A208: E1 | B208: Q2 | C208: Litter | D208: M | E208: 238.29 | F208: =MAX(E208-IF(D208="S",BagMasses!$B$12,IF(D208="M",BagMasses!$C$12,IF(D208="L",BagMasses!$D$12,IF(D208="SM",BagMasses!$E$12,IF(D208="E",BagMasses!$F$12))))),0) -> 211.872
A209: E1 | B209: Q3 | C209: Humulus japonicus | D209: M | E209: 39.48 | F209: =MAX(E209-IF(D209="S",BagMasses!$B$12,IF(D209="M",BagMasses!$C$12,IF(D209="L",BagMasses!$D$12,IF(D209="SM",BagMasses!$E$12,IF(D209="E",BagMasses!$F$12))))),0) -> 13.062
A210: E1 | B210: Q3 | C210: Litter | D210: S | E210: 163.05 | F210: =MAX(E210-IF(D210="S",BagMasses!$B$12,IF(D210="M",BagMasses!$C$12,IF(D210="L",BagMasses!$D$12,IF(D210="SM",BagMasses!$E$12,IF(D210="E",BagMasses!$F$12))))),0) -> 156.517
A211: E1 | B211: Q3 | C211: Phalaris arundinacea | D211: M | E211: 69.03 | F211: =MAX(E211-IF(D211="S",BagMasses!$B$12,IF(D211="M",BagMasses!$C$12,IF(D211="L",BagMasses!$D$12,IF(D211="SM",BagMasses!$E$12,IF(D211="E",BagMasses!$F$12))))),0) -> 42.612
A212: E1 | B212: Q4 | C212: Humulus japonicus | D212: S | E212: 11.68 | F212: =MAX(E212-IF(D212="S",BagMasses!$B$12,IF(D212="M",BagMasses!$C$12,IF(D212="L",BagMasses!$D$12,IF(D212="SM",BagMasses!$E$12,IF(D212="E",BagMasses!$F$12))))),0) -> 5.147
A213: E1 | B213: Q4 | C213: Litter | D213: M | E213: 171.73 | F213: =MAX(E213-IF(D213="S",BagMasses!$B$12,IF(D213="M",BagMasses!$C$12,IF(D213="L",BagMasses!$D$12,IF(D213="SM",BagMasses!$E$12,IF(D213="E",BagMasses!$F$12))))),0) -> 145.312
A214: E1 | B214: Q4 | C214: Phalaris arundinacea | D214: M | E214: 89.9 | F214: =MAX(E214-IF(D214="S",BagMasses!$B$12,IF(D214="M",BagMasses!$C$12,IF(D214="L",BagMasses!$D$12,IF(D214="SM",BagMasses!$E$12,IF(D214="E",BagMasses!$F$12))))),0) -> 63.482
A215: E1 | B215: Q5 | C215: Litter | D215: S | E215: 161.23 | F215: =MAX(E215-IF(D215="S",BagMasses!$B$12,IF(D215="M",BagMasses!$C$12,IF(D215="L",BagMasses!$D$12,IF(D215="SM",BagMasses!$E$12,IF(D215="E",BagMasses!$F$12))))),0) -> 154.697
A216: E1 | B216: Q5 | C216: Phalaris arundinacea | D216: M | E216: 71.5 | F216: =MAX(E216-IF(D216="S",BagMasses!$B$12,IF(D216="M",BagMasses!$C$12,IF(D216="L",BagMasses!$D$12,IF(D216="SM",BagMasses!$E$12,IF(D216="E",BagMasses!$F$12))))),0) -> 45.082
... A237: E3 | B237: Q2 | C237: Litter | D237: SM | E237: 123.36 | F237: =MAX(E237-IF(D237="S",BagMasses!$B$12,IF(D237="M",BagMasses!$C$12,IF(D237="L",BagMasses!$D$12,IF(D237="SM",BagMasses!$E$12,IF(D237="E",BagMasses!$F$12))))),0) -> 112.07333
A238: E3 | B238: Q2 | C238: Phalaris arundinacea | D238: SM | E238: 32.58 | F238: =MAX(E238-IF(D238="S",BagMasses!$B$12,IF(D238="M",BagMasses!$C$12,IF(D238="L",BagMasses!$D$12,IF(D238="SM",BagMasses!$E$12,IF(D238="E",BagMasses!$F$12))))),0) -> 21.293333 | G238: Initially unknown quadrat because bag not labelled
A239: E3 | B239: Q2 | C239: Pilea pumila | D239: E | E239: 2.93 | F239: =MAX(E239-IF(D239="S",BagMasses!$B$12,IF(D239="M",BagMasses!$C$12,IF(D239="L",BagMasses!$D$12,IF(D239="SM",BagMasses!$E$12,IF(D239="E",BagMasses!$F$12))))),0) -> 0
A240: E3 | B240: Q3 | C240: Humulus japonicus | D240: L | E240: 108.71 | F240: =MAX(E240-IF(D240="S",BagMasses!$B$12,IF(D240="M",BagMasses!$C$12,IF(D240="L",BagMasses!$D$12,IF(D240="SM",BagMasses!$E$12,IF(D240="E",BagMasses!$F$12))))),0) -> 41.106667
A241: E3 | B241: Q3 | C241: Humulus japonicus | D241: S | E241: 17.17 | F241: =MAX(E241-IF(D241="S",BagMasses!$B$12,IF(D241="M",BagMasses!$C$12,IF(D241="L",BagMasses!$D$12,IF(D241="SM",BagMasses!$E$12,IF(D241="E",BagMasses!$F$12))))),0) -> 10.637
...

Sheet BagMasses
B1: Small bag mass (g) | C1: Med bag mass (g) | D1: Large bag mass (g) | E1: Small-Medium bag mass (g) | F1: Envelope mass (g)
B2: 6.54 | C2: 26.54 | D2: 67.27 | E2: 11.2 | F2: 2.99
B3: 6.48 | C3: 26.5 | D3: 68.78 | E3: 11.32 | F3: 3.01
B4: 6.46 | C4: 26.41 | D4: 66.76 | E4: 11.34 | F4: 2.99
B5: 6.58 | C5: 26.58
B6: 6.54 | C6: 26.44
B7: 6.5 | C7: 26.32
B8: 6.61 | C8: 26.27
B9: 6.55 | C9: 26.53
B10: 6.48 | C10: 26.43
B11: 6.59 | C11: 26.16
A12: Average | B12: =AVERAGE(B2:B11) -> 6.533 | C12: =AVERAGE(C2:C11) -> 26.418 | D12: =AVERAGE(D2:D11) -> 67.603333 | E12: =AVERAGE(E2:E11) -> 11.286667 | F12: =AVERAGE(F2:F11) -> 2.9966667
